Workbook

Sheet 预计汇总（总）
A1: 2月份预计表
C2: 月初 | E2: 45683 | H2: 月初 | J2: 45683
A3: 公司 | B3: 项目分类 | C3: 可能回款 | D3: 确定回款 | E3: 可能回款 | F3: 确定回款 | G3: 实际回款 | H3: 月初可能合同 | I3: 月初确定合同 | J3: 可能合同 | K3: 确定合同 | L3: 实际合同
A4: 山东办事处汇总 | B4: 动环项目 | C4: ='预计汇总（详细）'!D14 -> 0 | D4: 0 | E4: 0 | F4: 0 | G4: 0 | H4: ='预计汇总（详细）'!I14 -> 0 | I4: ='预计汇总（详细）'!J14 -> 0 | J4: =山东办事处!F83 -> 0 | K4: =山东办事处!G83 -> 0 | L4: ='预计汇总（详细）'!M14 -> 0
B5: 地铁测温 | C5: ='预计汇总（详细）'!D15 -> 0 | D5: ='预计汇总（详细）'!E15 -> 0 | E5: ='预计汇总（详细）'!F15 -> 0 | F5: ='预计汇总（详细）'!G15 -> 0 | G5: ='预计汇总（详细）'!H15 -> 0 | H5: ='预计汇总（详细）'!I15 -> 0 | I5: ='预计汇总（详细）'!J15 -> 0 | J5: =山东办事处!F84 -> 0 | K5: =山东办事处!G84 -> 0 | L5: ='预计汇总（详细）'!M15 -> 0
B6: 煤矿项目 | C6: ='预计汇总（详细）'!D16 -> 0 | D6: ='预计汇总（详细）'!E16 -> 0 | E6: ='预计汇总（详细）'!F16 -> 0 | F6: ='预计汇总（详细）'!G16 -> 0 | G6: ='预计汇总（详细）'!H16 -> 0 | H6: ='预计汇总（详细）'!I16 -> 0 | I6: ='预计汇总（详细）'!J16 -> 0 | J6: =山东办事处!F85 -> 0 | K6: =山东办事处!G85 -> 0 | L6: ='预计汇总（详细）'!M16 -> 0
A7: 小计 | C7: =SUM(C4:C6) -> 0 | D7: =SUM(D4:D6) -> 0 | E7: =SUM(E4:E6) -> 0 | F7: =SUM(F4:F6) -> 0 | G7: =SUM(G4:G6) -> 0 | H7: =SUM(H4:H6) -> 0 | I7: =SUM(I4:I6) -> 0 | J7: =SUM(J4:J6) -> 0 | ... L7: =SUM(L4:L6) -> 0
A8: 天津子公司汇总 | B8: 动环项目 | C8: ='预计汇总（详细）'!D24 -> 0 | D8: ='预计汇总（详细）'!E24 -> 0 | E8: =天津子公司!F20 -> 0 | F8: =天津子公司!G20 -> 0 | G8: ='预计汇总（详细）'!H24 -> 0 | H8: ='预计汇总（详细）'!I24 -> 0 | I8: ='预计汇总（详细）'!J24 -> 0 | J8: ='预计汇总（详细）'!K24 -> 0 | K8: ='预计汇总（详细）'!L24 -> 0 | L8: ='预计汇总（详细）'!M24 -> 0
B9: 地铁测温 | C9: ='预计汇总（详细）'!D25 -> 0 | D9: ='预计汇总（详细）'!E25 -> 0 | E9: =天津子公司!F21 -> 0 | F9: =天津子公司!G21 -> 0 | G9: ='预计汇总（详细）'!H25 -> 0 | H9: ='预计汇总（详细）'!I25 -> 0 | I9: ='预计汇总（详细）'!J25 -> 0 | J9: ='预计汇总（详细）'!K25 -> 0 | K9: ='预计汇总（详细）'!L25 -> 0 | L9: ='预计汇总（详细）'!M25 -> 0
B10: 煤矿项目 | C10: ='预计汇总（详细）'!D26 -> 0 | D10: ='预计汇总（详细）'!E26 -> 0 | E10: =天津子公司!F22 -> 0 | F10: =天津子公司!G22 -> 0 | G10: ='预计汇总（详细）'!H26 -> 0 | H10: ='预计汇总（详细）'!I26 -> 0 | I10: ='预计汇总（详细）'!J26 -> 0 | J10: ='预计汇总（详细）'!K26 -> 0 | K10: ='预计汇总（详细）'!L26 -> 0 | L10: ='预计汇总（详细）'!M26 -> 0
A11: 小计 | C11: =SUM(C8:C10) -> 0 | D11: =SUM(D8:D10) -> 0 | E11: =SUM(E8:E10) -> 0 | F11: =SUM(F8:F10) -> 0 | G11: =SUM(G8:G10) -> 0 | H11: =SUM(H8:H10) -> 0 | I11: =SUM(I8:I10) -> 0 | J11: =SUM(J8:J10) -> 0 | ... L11: =SUM(L8:L10) -> 0
A12: 徐州办事处汇总 | B12: 动环项目 | C12: ='预计汇总（详细）'!D34 -> 0 | D12: ='预计汇总（详细）'!E34 -> 0 | E12: =徐州办事处!F35 -> 0 | F12: =徐州办事处!G35 -> 0 | G12: ='预计汇总（详细）'!H34 -> 0 | H12: ='预计汇总（详细）'!I34 -> 0 | I12: ='预计汇总（详细）'!J34 -> 0 | J12: =徐州办事处!F62 -> 0 | K12: =徐州办事处!G62 -> 0 | L12: ='预计汇总（详细）'!M34 -> 0
B13: 地铁测温 | C13: ='预计汇总（详细）'!D35 -> 0 | D13: ='预计汇总（详细）'!E35 -> 0 | E13: =徐州办事处!F36 -> 0 | F13: =徐州办事处!G36 -> 0 | G13: ='预计汇总（详细）'!H35 -> 0 | H13: ='预计汇总（详细）'!I35 -> 0 | I13: ='预计汇总（详细）'!J35 -> 0 | J13: =徐州办事处!F63 -> 0 | K13: =徐州办事处!G63 -> 0 | L13: ='预计汇总（详细）'!M35 -> 0
B14: 煤矿项目 | C14: ='预计汇总（详细）'!D36 -> 0 | D14: ='预计汇总（详细）'!E36 -> 0 | E14: =徐州办事处!F37 -> 0 | F14: =徐州办事处!G37 -> 0 | G14: ='预计汇总（详细）'!H36 -> 0 | H14: ='预计汇总（详细）'!I36 -> 0 | I14: ='预计汇总（详细）'!J36 -> 0 | J14: =徐州办事处!F64 -> 0 | K14: =徐州办事处!G64 -> 0 | L14: ='预计汇总（详细）'!M36 -> 0
A15: 小计 | C15: =SUM(C12:C14) -> 0 | D15: =SUM(D12:D14) -> 0 | E15: =SUM(E12:E14) -> 0 | F15: =SUM(F12:F14) -> 0 | G15: =SUM(G12:G14) -> 0 | H15: =SUM(H12:H14) -> 0 | I15: =SUM(I12:I14) -> 0 | J15: =SUM(J12:J14) -> 0 | ... L15: =SUM(L12:L14) -> 0
A16: 小计 | B16: 动环项目 | C16: ='预计汇总（详细）'!D38 -> 0 | D16: 0 | E16: =E4+E8+E12 -> 0 | F16: =F4+F8+F12 -> 0 | G16: ='预计汇总（详细）'!H38 -> 0 | H16: ='预计汇总（详细）'!I38 -> 0 | I16: ='预计汇总（详细）'!J38 -> 0 | J16: =J4+J8+J12 -> 0 | K16: =K4+K8+K12 -> 0 | L16: ='预计汇总（详细）'!M38 -> 0
B17: 地铁测温 | C17: ='预计汇总（详细）'!D39 -> 0 | D17: ='预计汇总（详细）'!E39 -> 0 | E17: =E5+E9+E13 -> 0 | F17: =F5+F9+F13 -> 0 | G17: ='预计汇总（详细）'!H39 -> 0 | H17: ='预计汇总（详细）'!I39 -> 0 | I17: ='预计汇总（详细）'!J39 -> 0 | J17: =J5+J9+J13 -> 0 | K17: =K5+K9+K13 -> 0 | L17: ='预计汇总（详细）'!M39 -> 0
B18: 煤矿项目 | C18: ='预计汇总（详细）'!D40 -> 0 | D18: ='预计汇总（详细）'!E40 -> 0 | E18: =E6+E10+E14 -> 0 | F18: =F6+F10+F14 -> 0 | G18: ='预计汇总（详细）'!H40 -> 0 | H18: ='预计汇总（详细）'!I40 -> 0 | I18: ='预计汇总（详细）'!J40 -> 0 | J18: =J6+J10+J14 -> 0 | K18: =K6+K10+K14 -> 0 | L18: ='预计汇总（详细）'!M40 -> 0
A19: 合计 | C19: =SUM(C16:C18) -> 0 | D19: =SUM(D16:D18) -> 0 | E19: =SUM(E16:E18) -> 0 | F19: =SUM(F16:F18) -> 0 | G19: =SUM(G16:G18) -> 0 | H19: =SUM(H16:H18) -> 0 | I19: =SUM(I16:I18) -> 0 | J19: =SUM(J16:J18) -> 0 | ... L19: =SUM(L16:L18) -> 0

Sheet 预计汇总（详细）
A1: 公司名 | B1: 负责人 | C1: 项目分类 | D1: 月初可能回款 | E1: 月初确定回款 | F1: 可能回款 | G1: 确定回款 | H1: 实际回款 | I1: 月初可能合同 | J1: 月初确定合同 | K1: 可能合同 | L1: 确定合同 | M1: 实际合同
A2: 山东办事处 | B2: 李晓林 | C2: 动环项目 | D2: =山东办事处!D7 -> 0 | E2: =山东办事处!E7 -> 0 | F2: =山东办事处!F7 -> 0 | G2: =山东办事处!G7 -> 0 | H2: =山东办事处!H7 -> 0 | I2: =山东办事处!D47 -> 0 | J2: =山东办事处!E47 -> 0 | K2: =山东办事处!F47 -> 0 | L2: =山东办事处!G47 -> 0 | M2: =山东办事处!H47 -> 0
C3: 地铁测温 | D3: =山东办事处!D9 -> 0 | E3: =山东办事处!E8 -> 0 | F3: =山东办事处!F9 -> 0 | G3: =山东办事处!G9 -> 0 | H3: =山东办事处!H9 -> 0 | I3: =山东办事处!D49 -> 0 | J3: =山东办事处!E49 -> 0 | K3: =山东办事处!F49 -> 0 | L3: =山东办事处!G48 -> 0 | M3: =山东办事处!H49 -> 0
C4: 煤矿项目 | D4: =山东办事处!D18 -> 0 | E4: =山东办事处!E9 -> 0 | F4: =山东办事处!F18 -> 0 | G4: =山东办事处!G11 -> 0 | H4: =山东办事处!H11 -> 0 | I4: =山东办事处!D51 -> 0 | J4: =山东办事处!E51 -> 0 | K4: =山东办事处!F51 -> 0 | L4: =山东办事处!G49 -> 0 | M4: =山东办事处!H51 -> 0
B5: 李大鹏 | C5: 动环项目 | D5: =山东办事处!D13 -> 0 | E5: =山东办事处!E13 -> 0 | F5: =山东办事处!F13 -> 0 | G5: =山东办事处!G13 -> 0 | H5: =山东办事处!H13 -> 0 | I5: =山东办事处!D56 -> 0 | J5: =山东办事处!E56 -> 0 | K5: =山东办事处!F56 -> 0 | L5: =山东办事处!G56 -> 0 | M5: =山东办事处!H56 -> 0
C6: 地铁测温 | D6: =山东办事处!D15 -> 0 | E6: =山东办事处!E15 -> 0 | F6: =山东办事处!F15 -> 0 | G6: =山东办事处!G15 -> 0 | H6: =山东办事处!H15 -> 0 | I6: =山东办事处!D58 -> 0 | J6: =山东办事处!E58 -> 0 | K6: =山东办事处!F58 -> 0 | L6: =山东办事处!G57 -> 0 | M6: =山东办事处!H58 -> 0
C7: 煤矿项目 | D7: =山东办事处!D18 -> 0 | E7: =山东办事处!E18 -> 0 | F7: =山东办事处!F18 -> 0 | G7: =山东办事处!G18 -> 0 | H7: =山东办事处!H18 -> 0 | I7: =山东办事处!D62 -> 0 | J7: =山东办事处!E62 -> 0 | K7: =山东办事处!F62 -> 0 | L7: =山东办事处!G62 -> 0 | M7: =山东办事处!H62 -> 0
B8: 李金芳 | C8: 动环项目 | D8: =山东办事处!D22 -> 0 | E8: =山东办事处!E22 -> 0 | F8: =山东办事处!F22 -> 0 | G8: =山东办事处!G22 -> 0 | H8: =山东办事处!H22 -> 0 | I8: =山东办事处!D68 -> 0 | J8: =山东办事处!E68 -> 0 | K8: =山东办事处!F68 -> 0 | L8: =山东办事处!G68 -> 0 | M8: =山东办事处!H68 -> 0
C9: 地铁测温 | D9: =山东办事处!D24 -> 0 | E9: =山东办事处!E24 -> 0 | F9: =山东办事处!F24 -> 0 | G9: =山东办事处!G24 -> 0 | H9: =山东办事处!H24 -> 0 | I9: =山东办事处!D70 -> 0 | J9: =山东办事处!E70 -> 0 | K9: =山东办事处!F70 -> 0 | L9: =山东办事处!G70 -> 0 | M9: =山东办事处!H70 -> 0
C10: 煤矿项目 | D10: =山东办事处!D27 -> 0 | E10: =山东办事处!E27 -> 0 | F10: =山东办事处!F27 -> 0 | G10: =山东办事处!G27 -> 0 | H10: =山东办事处!H27 -> 0 | I10: =山东办事处!D73 -> 0 | J10: =山东办事处!E73 -> 0 | K10: =山东办事处!F73 -> 0 | L10: =山东办事处!G73 -> 0 | M10: =山东办事处!H73 -> 0
B11: 孙旭光 | C11: 动环项目 | D11: =山东办事处!D31 -> 0 | E11: =山东办事处!E31 -> 0 | F11: =山东办事处!F31 -> 0 | G11: =山东办事处!G31 -> 0 | H11: =山东办事处!H31 -> 0 | I11: =山东办事处!D77 -> 0 | J11: =山东办事处!E77 -> 0 | K11: =山东办事处!F77 -> 0 | L11: =山东办事处!G77 -> 0 | M11: =山东办事处!H77 -> 0
C12: 地铁测温 | D12: =山东办事处!D33 -> 0 | E12: =山东办事处!E33 -> 0 | F12: =山东办事处!F33 -> 0 | G12: =山东办事处!G33 -> 0 | H12: =山东办事处!H33 -> 0 | I12: =山东办事处!D79 -> 0 | J12: =山东办事处!E79 -> 0 | K12: =山东办事处!F79 -> 0 | L12: =山东办事处!G79 -> 0 | M12: =山东办事处!H79 -> 0
C13: 煤矿项目 | D13: =山东办事处!D35 -> 0 | E13: =山东办事处!E35 -> 0 | F13: =山东办事处!F35 -> 0 | G13: =山东办事处!G35 -> 0 | H13: =山东办事处!H35 -> 0 | I13: =山东办事处!D82 -> 0 | J13: =山东办事处!E82 -> 0 | K13: =山东办事处!F82 -> 0 | L13: =山东办事处!G82 -> 0 | M13: =山东办事处!H82 -> 0
B14: 山东办事处汇总 | C14: 动环项目 | D14: =D2+D5+D8+D11 -> 0 | E14: =E2+E5+E8+E11 -> 0 | F14: =F2+F5+F8+F11 -> 0 | G14: =G2+G5+G8+G11 -> 0 | H14: =H2+H5+H8+H11 -> 0 | I14: =I2+I5+I8+I11 -> 0 | J14: =J2+J5+J8+J11 -> 0 | K14: =K2+K5+K8+K11 -> 0 | ... M14: =M2+M5+M8+M11 -> 0
C15: 地铁测温 | D15: =D3+D6+D9+D12 -> 0 | E15: =E3+E6+E9+E12 -> 0 | F15: =F3+F6+F9+F12 -> 0 | G15: =G3+G6+G9+G12 -> 0 | H15: =H3+H6+H9+H12 -> 0 | I15: =I3+I6+I9+I12 -> 0 | J15: =J3+J6+J9+J12 -> 0 | K15: =K3+K6+K9+K12 -> 0 | ... M15: =M3+M6+M9+M12 -> 0
C16: 煤矿项目 | D16: =D4+D7+D10+D13 -> 0 | E16: =E4+E7+E10+E13 -> 0 | F16: =F4+F7+F10+F13 -> 0 | G16: =G4+G7+G10+G13 -> 0 | H16: =H4+H7+H10+H13 -> 0 | I16: =I4+I7+I10+I13 -> 0 | J16: =J4+J7+J10+J13 -> 0 | K16: =K4+K7+K10+K13 -> 0 | ... M16: =M4+M7+M10+M13 -> 0
B17: 小计 | D17: =SUM(D14:D16) -> 0 | E17: =SUM(E14:E16) -> 0 | F17: =SUM(F14:F16) -> 0 | G17: =SUM(G14:G16) -> 0 | H17: =SUM(H14:H16) -> 0 | I17: =SUM(I14:I16) -> 0 | J17: =SUM(J14:J16) -> 0 | K17: =SUM(K14:K16) -> 0 | ... M17: =SUM(M14:M16) -> 0
A18: 天津子公司 | B18: 丁俊 | C18: 动环项目 | D18: =天津子公司!D14 -> 0 | E18: =天津子公司!E14 -> 0 | F18: =天津子公司!F14 -> 0 | G18: =天津子公司!G14 -> 0 | H18: =天津子公司!H14 -> 0 | I18: =天津子公司!D27 -> 0 | J18: =天津子公司!E27 -> 0 | K18: =天津子公司!F27 -> 0 | L18: =天津子公司!G27 -> 0 | M18: =天津子公司!H27 -> 0
C19: 地铁测温 | D19: =天津子公司!D16 -> 0 | E19: =天津子公司!E16 -> 0 | F19: =天津子公司!F16 -> 0 | G19: =天津子公司!G16 -> 0 | H19: =天津子公司!H16 -> 0 | I19: =天津子公司!D29 -> 0 | J19: =天津子公司!E29 -> 0 | K19: =天津子公司!F29 -> 0 | L19: =天津子公司!G29 -> 0 | M19: =天津子公司!H29 -> 0
C20: 煤矿项目 | D20: =天津子公司!D19 -> 0 | E20: =天津子公司!E19 -> 0 | F20: =天津子公司!F19 -> 0 | G20: =天津子公司!G19 -> 0 | H20: =天津子公司!H19 -> 0 | I20: =天津子公司!D32 -> 0 | J20: =天津子公司!E32 -> 0 | K20: =天津子公司!F32 -> 0 | L20: =天津子公司!G32 -> 0 | M20: =天津子公司!H32 -> 0
B21: 隋亚林 | C21: 动环项目 | D21: =天津子公司!D5 -> 0 | E21: =天津子公司!E5 -> 0 | F21: =天津子公司!F5 -> 0 | G21: =天津子公司!G5 -> 0 | H21: =天津子公司!H5 -> 0 | I21: =天津子公司!D35 -> 0 | J21: =天津子公司!E35 -> 0 | K21: =天津子公司!F35 -> 0 | L21: =天津子公司!G35 -> 0 | M21: =天津子公司!H35 -> 0
C22: 地铁测温 | D22: =天津子公司!D7 -> 0 | E22: =天津子公司!E7 -> 0 | F22: =天津子公司!F7 -> 0 | G22: =天津子公司!G7 -> 0 | H22: =天津子公司!H7 -> 0 | I22: =天津子公司!D37 -> 0 | J22: =天津子公司!E37 -> 0 | K22: =天津子公司!F37 -> 0 | L22: =天津子公司!G37 -> 0 | M22: =天津子公司!H37 -> 0
C23: 煤矿项目 | D23: =天津子公司!D10 -> 0 | E23: =天津子公司!E10 -> 0 | F23: =天津子公司!F10 -> 0 | G23: =天津子公司!G10 -> 0 | H23: =天津子公司!H10 -> 0 | I23: =天津子公司!D40 -> 0 | J23: =天津子公司!E40 -> 0 | K23: =天津子公司!F40 -> 0 | L23: =天津子公司!G40 -> 0 | M23: =天津子公司!H40 -> 0
B24: 天津子公司汇总 | C24: 动环项目 | D24: =D18+D21 -> 0 | E24: =E18+E21 -> 0 | F24: =F18+F21 -> 0 | G24: =G18+G21 -> 0 | H24: =H18+H21 -> 0 | I24: =I18+I21 -> 0 | J24: =J18+J21 -> 0 | K24: =K18+K21 -> 0 | ... M24: =M18+M21 -> 0
C25: 地铁测温 | D25: =D19+D22 -> 0 | E25: =E19+E22 -> 0 | F25: =F19+F22 -> 0 | G25: =G19+G22 -> 0 | H25: =H19+H22 -> 0 | I25: =I19+I22 -> 0 | J25: =J19+J22 -> 0 | K25: =K19+K22 -> 0 | ... M25: =M19+M22 -> 0
C26: 煤矿项目 | D26: =D20+D23 -> 0 | E26: =E20+E23 -> 0 | F26: =F20+F23 -> 0 | G26: =G20+G23 -> 0 | H26: =H20+H23 -> 0 | I26: =I20+I23 -> 0 | J26: =J20+J23 -> 0 | K26: =K20+K23 -> 0 | ... M26: =M20+M23 -> 0
B27: 小计 | D27: =SUM(D24:D26) -> 0 | E27: =SUM(E24:E26) -> 0 | F27: =SUM(F24:F26) -> 0 | G27: =SUM(G24:G26) -> 0 | H27: =SUM(H24:H26) -> 0 | I27: =SUM(I24:I26) -> 0 | J27: =SUM(J24:J26) -> 0 | K27: =SUM(K24:K26) -> 0 | ... M27: =SUM(M24:M26) -> 0
A28: 徐州办事处 | B28: 杨志龙 | C28: 动环项目 | D28: =徐州办事处!D28 -> 0 | E28: =徐州办事处!E28 -> 0 | F28: =徐州办事处!F28 -> 0 | G28: =徐州办事处!G28 -> 0 | H28: =徐州办事处!H28 -> 0 | I28: =徐州办事处!D56 -> 0 | J28: =徐州办事处!E56 -> 0 | K28: =徐州办事处!F56 -> 0 | L28: =徐州办事处!G56 -> 0 | M28: =徐州办事处!H56 -> 0
C29: 地铁测温 | D29: =徐州办事处!D31 -> 0 | E29: =徐州办事处!E31 -> 0 | F29: =徐州办事处!F31 -> 0 | G29: =徐州办事处!G31 -> 0 | H29: =徐州办事处!H31 -> 0 | I29: =徐州办事处!D58 -> 0 | J29: =徐州办事处!E58 -> 0 | K29: =徐州办事处!F58 -> 0 | L29: =徐州办事处!G58 -> 0 | M29: =徐州办事处!H58 -> 0
C30: 煤矿项目 | D30: =徐州办事处!D34 -> 0 | E30: =徐州办事处!E34 -> 0 | F30: =徐州办事处!F34 -> 0 | G30: =徐州办事处!G34 -> 0 | H30: =徐州办事处!H34 -> 0 | I30: =徐州办事处!D61 -> 0 | J30: =徐州办事处!E61 -> 0 | K30: =徐州办事处!F61 -> 0 | L30: =徐州办事处!G61 -> 0 | M30: =徐州办事处!H61 -> 0
B31: 付海元 | C31: 动环项目 | D31: =徐州办事处!D5 -> 0 | E31: =徐州办事处!E5 -> 0 | F31: =徐州办事处!F5 -> 0 | G31: =徐州办事处!G5 -> 0 | H31: =徐州办事处!H5 -> 0 | I31: =徐州办事处!D42 -> 0 | J31: =徐州办事处!E42 -> 0 | K31: =徐州办事处!F42 -> 0 | L31: =徐州办事处!G42 -> 0 | M31: =徐州办事处!H42 -> 0
C32: 地铁测温 | D32: =徐州办事处!D8 -> 0 | E32: =徐州办事处!E8 -> 0 | F32: =徐州办事处!F8 -> 0 | G32: =徐州办事处!G8 -> 0 | H32: =徐州办事处!H8 -> 0 | I32: =徐州办事处!D44 -> 0 | J32: =徐州办事处!E44 -> 0 | K32: =徐州办事处!F44 -> 0 | L32: =徐州办事处!G44 -> 0 | M32: =徐州办事处!H44 -> 0
C33: 煤矿项目 | D33: =徐州办事处!D26 -> 0 | E33: =徐州办事处!E26 -> 0 | F33: =徐州办事处!F26 -> 0 | G33: =徐州办事处!G26 -> 0 | H33: =徐州办事处!H26 -> 0 | I33: =徐州办事处!D53 -> 0 | J33: =徐州办事处!E53 -> 0 | K33: =徐州办事处!F53 -> 0 | L33: =徐州办事处!G53 -> 0 | M33: =徐州办事处!H53 -> 0
B34: 徐州办事处汇总 | C34: 动环项目 | D34: =D28+D31 -> 0 | E34: =E28+E31 -> 0 | F34: =F28+F31 -> 0 | G34: =G28+G31 -> 0 | H34: =H28+H31 -> 0 | I34: =I28+I31 -> 0 | J34: =J28+J31 -> 0 | K34: =K28+K31 -> 0 | ... M34: =M28+M31 -> 0
C35: 地铁测温 | D35: =D29+D32 -> 0 | E35: =E29+E32 -> 0 | F35: =F29+F32 -> 0 | G35: =G29+G32 -> 0 | H35: =H29+H32 -> 0 | I35: =I29+I32 -> 0 | J35: =J29+J32 -> 0 | K35: =K29+K32 -> 0 | ... M35: =M29+M32 -> 0
C36: 煤矿项目 | D36: =D30+D33 -> 0 | E36: =E30+E33 -> 0 | F36: =F30+F33 -> 0 | G36: =G30+G33 -> 0 | H36: =H30+H33 -> 0 | I36: =I30+I33 -> 0 | J36: =J30+J33 -> 0 | K36: =K30+K33 -> 0 | ... M36: =M30+M33 -> 0
B37: 小计 | D37: =SUM(D34:D36) -> 0 | E37: =SUM(E34:E36) -> 0 | F37: =SUM(F34:F36) -> 0 | G37: =SUM(G34:G36) -> 0 | H37: =SUM(H34:H36) -> 0 | I37: =SUM(I34:I36) -> 0 | J37: =SUM(J34:J36) -> 0 | K37: =SUM(K34:K36) -> 0 | ... M37: =SUM(M34:M36) -> 0
B38: 小计 | C38: 动环项目 | D38: =D14+D24+D34 -> 0 | E38: =E14+E24+E34 -> 0 | F38: =F14+F24+F34 -> 0 | G38: =G14+G24+G34 -> 0 | H38: =H14+H24+H34 -> 0 | I38: =I14+I24+I34 -> 0 | J38: =J14+J24+J34 -> 0 | K38: =K14+K24+K34 -> 0 | ... M38: =M14+M24+M34 -> 0
C39: 地铁测温 | D39: =D15+D25+D35 -> 0 | E39: =E15+E25+E35 -> 0 | F39: =F15+F25+F35 -> 0 | G39: =G15+G25+G35 -> 0 | H39: =H15+H25+H35 -> 0 | I39: =I15+I25+I35 -> 0 | J39: =J15+J25+J35 -> 0 | K39: =K15+K25+K35 -> 0 | ... M39: =M15+M25+M35 -> 0
C40: 煤矿项目 | D40: =D16+D26+D36 -> 0 | E40: =E16+E26+E36 -> 0 | F40: =F16+F26+F36 -> 0 | G40: =G16+G26+G36 -> 0 | H40: =H16+H26+H36 -> 0 | I40: =I16+I26+I36 -> 0 | J40: =J16+J26+J36 -> 0 | K40: =K16+K26+K36 -> 0 | ... M40: =M16+M26+M36 -> 0
...

Sheet 山东办事处
A1: 2月份预计回款 | J1: 2026年2月1日——2月28日
A2: 负责人 | B2: 项目类型 | C2: 项目名称 | D2: 月初预计可能回款 | E2: 月初预计确定回款 | F2: 可能回款 | G2: 确定回款 | H2: 实际回款 | I2: 未回款金额 | J2: 未完成原因 | K2: 解决办法
A3: 李晓林 | B3: 动环项目 | E3: 0
C7: 小计 | D7: =SUM(D3:D6) -> 0 | E7: =SUM(E3:E6) -> 0 | F7: =SUM(F3:F6) -> 0 | G7: =SUM(G3:G6) -> 0 | H7: =SUM(H3:H6) -> 0
B8: 地铁测温 | G8: 0
C9: 小计 | D9: =SUM(D8) -> 0 | E9: =SUM(E8) -> 0 | F9: =SUM(F8) -> 0 | G9: =SUM(G8) -> 0 | H9: =SUM(H8) -> 0
B10: 煤矿项目 | G10: 0
C11: 小计 | D11: =SUM(D10) -> 0 | E11: =SUM(E10) -> 0 | F11: =SUM(F10) -> 0 | G11: =SUM(G10) -> 0 | H11: =SUM(H10) -> 0
A12: 李大鹏 | B12: 动环项目
C13: 小计 | D13: =SUM(D12:D12) -> 0 | E13: =SUM(E12:E12) -> 0 | F13: =SUM(F12:F12) -> 0 | G13: =SUM(G12:G12) -> 0 | H13: =SUM(H12:H12) -> 0
B14: 地铁测温
C15: 小计 | D15: =SUM(D14) -> 0 | E15: =SUM(E14) -> 0 | F15: =SUM(F14) -> 0 | G15: =SUM(G14) -> 0 | H15: =SUM(H14) -> 0
B16: 煤矿项目
C18: 小计 | D18: =SUM(D16:D17) -> 0 | E18: =SUM(E16:E17) -> 0 | F18: =SUM(F16:F17) -> 0 | G18: =SUM(G16:G17) -> 0 | H18: =SUM(H16:H17) -> 0
A19: 李金芳 | B19: 动环项目
C22: 小计 | D22: =SUM(D19:D21) -> 0 | E22: =SUM(E19:E21) -> 0 | F22: =SUM(F19:F21) -> 0 | G22: =SUM(G19:G21) -> 0 | H22: =SUM(H19:H21) -> 0
B23: 地铁测温
B24: 地铁测温 | C24: 小计 | D24: =SUM(D23) -> 0 | E24: =SUM(E23) -> 0 | F24: =SUM(F23) -> 0 | G24: =SUM(G23) -> 0 | H24: =SUM(H23) -> 0
B25: 煤矿项目
B27: 煤矿项目 | C27: 小计 | D27: =SUM(D25:D26) -> 0 | E27: =SUM(E25:E26) -> 0 | F27: =SUM(F25:F26) -> 0 | G27: =SUM(G25:G26) -> 0 | H27: =SUM(H25:H26) -> 0
A28: 孙旭光 | B28: 动环项目
C31: 小计 | D31: =SUM(D28:D30) -> 0 | E31: =SUM(E28:E30) -> 0 | F31: =SUM(F28:F30) -> 0 | G31: =SUM(G28:G30) -> 0 | H31: =SUM(H28:H30) -> 0
B32: 地铁测温
B33: 地铁测温 | C33: 小计 | D33: =SUM(D32) -> 0 | E33: =SUM(E32) -> 0 | F33: =SUM(F32) -> 0 | G33: =SUM(G32) -> 0 | H33: =SUM(H32) -> 0
B34: 市政项目
B35: 煤矿项目 | C35: 小计 | D35: =SUM(D34:D34) -> 0 | E35: =SUM(E34:E34) -> 0 | F35: =SUM(F34:F34) -> 0 | G35: =SUM(G34:G34) -> 0 | H35: =SUM(H34:H34) -> 0
A36: 山东办事处汇总 | B36: 动环项目 | D36: =D7+D13+D22+D31 -> 0 | E36: =E7+E13+E22+E31 -> 0 | F36: =F7+F13+F22+F31 -> 0 | G36: =G7+G13+G22+G31 -> 0 | H36: =H7+H13+H22+H31 -> 0
B37: 地铁测温 | D37: =D9+D15+D24+D33 -> 0 | E37: =E9+E15+E24+E33 -> 0 | F37: =F9+F15+F24+F33 -> 0 | G37: =G9+G15+G24+G33 -> 0 | H37: =H9+H15+H24+H33 -> 0
B38: 煤矿项目 | D38: =D11+D18+D27+D35 -> 0 | E38: =E11+E18+E27+E35 -> 0 | F38: =F11+F18+F27+F35 -> 0 | G38: =G11+G18+G27+G35 -> 0 | H38: =H11+H18+H27+H35 -> 0
B39: 2月份预计合同
A40: 负责人 | B40: 公司名称 | C40: 项目名称 | D40: 月初预计可能合同 | E40: 月初预计确定合同 | F40: 可能合同 | G40: 确定合同 | H40: 实际合同 | J40: 完成情况
A41: 李晓林 | B41: 动环项目
C47: 小计 | D47: =SUM(D41:D46) -> 0 | E47: =SUM(E41:E46) -> 0 | F47: =SUM(F41:F46) -> 0 | G47: =SUM(G41:G46) -> 0 | H47: =SUM(H41:H46) -> 0
B48: 地铁测温 | G48: 0
C49: 小计 | D49: =SUM(D48) -> 0 | E49: =SUM(E48) -> 0 | F49: =SUM(F48) -> 0 | G49: =SUM(G48) -> 0 | H49: =SUM(H48) -> 0
B50: 煤矿项目 | G50: 0
C51: 小计 | D51: =SUM(D50) -> 0 | E51: =SUM(E50) -> 0 | F51: =SUM(F50) -> 0 | G51: =SUM(G50) -> 0 | H51: =SUM(H50) -> 0
A52: 李大鹏 | B52: 动环项目
C56: 小计 | D56: =SUM(D52:D55) -> 0 | E56: =SUM(E52:E55) -> 0 | F56: =SUM(F52:F55) -> 0 | G56: =SUM(G52:G55) -> 0 | H56: =SUM(H52:H55) -> 0
B57: 地铁测温 | G57: 0
...

Sheet 徐州办事处
A1: 2月份预计回款 | K1: 2026年2月1日—2月28日
A2: 负责人 | B2: 项目类型 | C2: 项目名称 | D2: 月初预计可能回款 | E2: 月初预计确定回款 | F2: 可能回款 | G2: 确定回款 | H2: 实际回款 | I2: 回款节点确定 | J2: 回款节点 | K2: 未完成原因 | L2: 解决办法
A3: 付海元 | B3: 动环项目
C5: 小计 | D5: =SUM(D3:D4) -> 0 | E5: =SUM(E3:E4) -> 0 | F5: =SUM(F3:F4) -> 0 | G5: =SUM(G3:G4) -> 0 | H5: =SUM(H3:H4) -> 0
B6: 地铁测温
C8: 小计 | D8: =SUM(D6:D7) -> 0 | E8: =SUM(E6:E7) -> 0 | F8: =SUM(F6:F7) -> 0 | G8: =SUM(G6:G7) -> 0 | H8: =SUM(H6:H7) -> 0
C26: 小计 | D26: =SUM(D9:D25) -> 0 | E26: =SUM(E9:E25) -> 0 | F26: =SUM(F9:F25) -> 0 | G26: =SUM(G9:G25) -> 0 | H26: =SUM(H10:H25) -> 0
A27: 杨志龙 | B27: 动环项目
C28: 小计 | D28: =SUM(D27) -> 0 | E28: =SUM(E27) -> 0 | F28: =SUM(F27) -> 0 | G28: =SUM(G27) -> 0 | H28: =SUM(H27) -> 0
B29: 地铁测温
B31: 地铁测温 | C31: 小计 | D31: =SUM(D29:D30) -> 0 | E31: =SUM(E29:E30) -> 0 | F31: =SUM(F29:F30) -> 0 | G31: =SUM(G29:G30) -> 0 | H31: =SUM(H29:H30) -> 0
B32: 煤矿项目
B34: 煤矿项目 | C34: 小计 | D34: =SUM(D32:D33) -> 0 | E34: =SUM(E32:E33) -> 0 | F34: =SUM(F32:F33) -> 0 | G34: =SUM(G32:G33) -> 0 | H34: =SUM(H32:H33) -> 0
A35: 徐州办事处汇总 | B35: 动环项目 | D35: =D5+D28 -> 0 | E35: =E5+E28 -> 0 | F35: =F5+F28 -> 0 | G35: =G5+G28 -> 0 | H35: =H5+H28 -> 0
B36: 地铁测温 | D36: =D6+D29 -> 0 | E36: =E8+E31 -> 0 | F36: =F8+F31 -> 0 | G36: =G8+G31 -> 0 | H36: =H8+H31 -> 0
B37: 煤矿项目 | D37: =D34+D26 -> 0 | E37: =E26+E34 -> 0 | F37: =F26+F34 -> 0 | G37: =G26+G34 -> 0 | H37: =H26+H34 -> 0
A38: 2月份预计合同
A39: 负责人 | B39: 公司名称 | C39: 项目名称 | D39: 月初预计可能合同 | E39: 月初预计确定合同 | F39: 可能合同 | G39: 确定合同 | H39: 实际合同 | J39: 完成情况
A40: 付海元 | B40: 动环项目
C42: 小计 | D42: =SUM(D40:D41) -> 0 | E42: =SUM(E40:E41) -> 0 | F42: =SUM(F40:F41) -> 0 | G42: =SUM(G40:G41) -> 0 | H42: =SUM(H40:H41) -> 0
B43: 地铁测温 | G43: 0
C44: 小计 | D44: =SUM(D43) -> 0 | E44: =SUM(E43) -> 0 | F44: =SUM(F43) -> 0 | G44: =SUM(G43) -> 0 | H44: =SUM(H43) -> 0
B45: 煤矿项目
C53: 小计 | D53: =SUM(D45:D52) -> 0 | E53: =SUM(E45:E52) -> 0 | F53: =SUM(F45:F52) -> 0 | G53: =SUM(G45:G52) -> 0 | H53: =SUM(H45:H52) -> 0
A54: 杨志龙 | B54: 动环项目
C56: 小计 | D56: =SUM(D54:D55) -> 0 | E56: =SUM(E54:E55) -> 0 | F56: =SUM(F54:F55) -> 0 | G56: =SUM(G54:G55) -> 0 | H56: =SUM(H54:H55) -> 0
B57: 地铁测温
C58: 小计 | D58: =SUM(D57) -> 0 | E58: =SUM(E57) -> 0 | F58: =SUM(F57) -> 0 | G58: =SUM(G57) -> 0 | H58: =SUM(H57) -> 0
B59: 煤矿项目
C61: 小计 | D61: =SUM(D59:D60) -> 0 | E61: =SUM(E59:E60) -> 0 | F61: =SUM(F59:F60) -> 0 | G61: =SUM(G59:G60) -> 0 | H61: =SUM(H59:H60) -> 0
A62: 徐州办事处汇总 | B62: 动环项目 | D62: =D42+D56 -> 0 | E62: =E42+E56 -> 0 | F62: =F42+F56 -> 0 | G62: =G42+G56 -> 0 | H62: =H42+H56 -> 0
B63: 地铁测温 | D63: =D44+D58 -> 0 | E63: =E44+E58 -> 0 | F63: =F44+F58 -> 0 | G63: =G44+G58 -> 0 | H63: =H44+H58 -> 0
B64: 煤矿项目 | D64: =D53+D61 -> 0 | E64: =E53+E61 -> 0 | F64: =F53+F61 -> 0 | G64: =G53+G61 -> 0 | H64: =H53+H61 -> 0
A67: 2月份预计施工

Sheet 天津子公司
A1: 2月份预计回款 | I1: 2026年2月1日——2月28日
A2: 负责人 | B2: 项目类型 | C2: 项目名称 | D2: 月初预计可能回款 | E2: 月初预计确定回款 | F2: 可能回款 | G2: 确定回款 | H2: 实际回款 | I2: 未完成原因 | J2: 解决办法
A3: 隋亚林 | B3: 动环项目
C5: 小计 | D5: =SUM(D3:D4) -> 0 | E5: =SUM(E3:E4) -> 0 | F5: =SUM(F3:F4) -> 0 | G5: =SUM(G3:G4) -> 0 | H5: =SUM(H3:H4) -> 0
B6: 地铁测温
B7: 地铁测温 | C7: 小计 | D7: =SUM(D6) -> 0 | E7: =SUM(E6) -> 0 | F7: =SUM(F6) -> 0 | G7: =SUM(G6) -> 0 | H7: =SUM(H6) -> 0
B8: 煤矿项目
B10: 煤矿项目 | C10: 小计 | D10: =SUM(D8:D9) -> 0 | E10: =SUM(E8:E9) -> 0 | F10: =SUM(F8:F9) -> 0 | G10: =SUM(G8:G9) -> 0 | H10: =SUM(H8:H9) -> 0
A11: 丁俊 | B11: 动环项目
C14: 小计 | D14: =SUM(D11:D13) -> 0 | E14: =SUM(E11:E13) -> 0 | F14: =SUM(F11:F13) -> 0 | G14: =SUM(G11:G13) -> 0 | H14: =SUM(H11:H13) -> 0
B15: 地铁测温
B16: 地铁测温 | C16: 小计 | D16: =SUM(D15) -> 0 | E16: =SUM(E15) -> 0 | F16: =SUM(F15) -> 0 | G16: =SUM(G15) -> 0 | H16: =SUM(H15) -> 0
B17: 煤矿项目
B19: 煤矿项目 | C19: 小计 | D19: =SUM(D17:D18) -> 0 | E19: =SUM(E17:E18) -> 0 | F19: =SUM(F17:F18) -> 0 | G19: =SUM(G17:G18) -> 0 | H19: =SUM(H17:H18) -> 0
A20: 天津子公司汇总 | B20: 动环项目 | D20: =D5+D14 -> 0 | E20: =E5+E14 -> 0 | F20: =F5+F14 -> 0 | G20: =G5+G14 -> 0 | H20: =H5+H14 -> 0
B21: 地铁测温 | D21: =D7+D16 -> 0 | E21: =E7+E16 -> 0 | F21: =F7+F16 -> 0 | G21: =G7+G16 -> 0 | H21: =H7+H16 -> 0
B22: 煤矿项目 | D22: =D10+D19 -> 0 | E22: =E10+E19 -> 0 | F22: =F10+F19 -> 0 | G22: =G10+G19 -> 0 | H22: =H10+H19 -> 0
A23: 2月份预计合同
A24: 负责人 | B24: 公司名称 | C24: 项目名称 | D24: 月初预计可能合同 | E24: 月初预计确定合同 | F24: 可能合同 | G24: 确定合同 | H24: 实际合同 | I24: 完成情况
A25: 丁俊 | B25: 动环项目
C27: 小计 | D27: =SUM(D25:D26) -> 0 | E27: =SUM(E25:E26) -> 0 | F27: =SUM(F25:F26) -> 0 | G27: =SUM(G25:G26) -> 0 | H27: =SUM(H25:H26) -> 0
B28: 地铁测温
B29: 地铁测温 | C29: 小计 | D29: =SUM(D28) -> 0 | E29: =SUM(E28) -> 0 | F29: =SUM(F28) -> 0 | G29: =SUM(G28) -> 0 | H29: =SUM(H28) -> 0
B30: 煤矿项目
B32: 煤矿项目 | C32: 小计 | D32: =SUM(D30:D31) -> 0 | E32: =SUM(E30:E31) -> 0 | F32: =SUM(F30:F31) -> 0 | G32: =SUM(G30:G31) -> 0 | H32: =SUM(H30:H31) -> 0
A33: 隋亚林 | B33: 动环项目
C35: 小计 | D35: =SUM(D33:D34) -> 0 | E35: =SUM(E33:E34) -> 0 | F35: =SUM(F33:F34) -> 0 | G35: =SUM(G33:G34) -> 0 | H35: =SUM(H33:H34) -> 0
B36: 地铁测温 | G36: 0
C37: 小计 | D37: =SUM(D36) -> 0 | E37: =SUM(E36) -> 0 | F37: =SUM(F36) -> 0 | G37: =SUM(G36) -> 0 | H37: =SUM(H36) -> 0
B38: 煤矿项目
C40: 小计 | E40: =SUM(E38:E38) -> 0 | F40: =SUM(F38:F38) -> 0 | G40: =SUM(G38:G39) -> 0 | H40: =SUM(H38:H39) -> 0
A41: 天津子公司汇总 | B41: 动环项目 | D41: =D27+D35 -> 0 | E41: =E27+E35 -> 0 | F41: =F27+F35 -> 0 | G41: =G27+G35 -> 0 | H41: =H27+H35 -> 0
B42: 地铁测温 | D42: =D29+D37 -> 0 | E42: =E29+E37 -> 0 | F42: =F29+F37 -> 0 | G42: =G29+G37 -> 0 | H42: =H29+H37 -> 0
B43: 煤矿项目 | D43: =D32+D40 -> 0 | E43: =E32+E40 -> 0 | F43: =F32+F40 -> 0 | G43: =G32+G40 -> 0 | H43: =H32+H40 -> 0
A45: 2月份预计施工
